// Handle a Rejected Promise with catch
// catch is the method used when your promise has been rejected. It is executed immediately after a promise's reject method is called. Hereâ€™s the syntax:

// myPromise.catch(error => {
  
// });
// error is the argument passed in to the reject method.

// Add the catch method to your promise. Use error as the parameter of its callback function and log error to the console.

const makePromise = new Promise((resolve,reject) => {
    // let responseFromServer = true;
    let responseFromServer = false;

    if(responseFromServer){
        resolve("We got the data");
    }else{
        reject("Data not found");
    }
});

makePromise.then(result => {
    console.log(result);
})

makePromise.catch(error => {
    console.log(error);
})
    
